2020-01-09 20:13:42,136 INFO controller Points Captured. [(864, 637), (262, 707)]
2020-01-09 20:13:46,378 INFO controller all certificates generated successfully
2020-01-09 20:13:59,410 INFO controller mailer failed due to the following reason
2020-01-09 20:13:59,414 INFO controller Traceback (most recent call last):
  File "/Users/ajayraj/Documents/GitHub/Certificate-Generator/controller.py", line 146, in email_certificates
    mailer = Mailer(target_dir, mailing_list)
  File "/Users/ajayraj/Documents/GitHub/Certificate-Generator/mailer.py", line 26, in __init__
    self.server.login(self.login_email, self.login_password)
  File "/Library/Frameworks/Python.framework/Versions/3.6/lib/python3.6/smtplib.py", line 730, in login
    raise last_exception
  File "/Library/Frameworks/Python.framework/Versions/3.6/lib/python3.6/smtplib.py", line 721, in login
    initial_response_ok=initial_response_ok)
  File "/Library/Frameworks/Python.framework/Versions/3.6/lib/python3.6/smtplib.py", line 642, in auth
    raise SMTPAuthenticationError(code, resp)
smtplib.SMTPAuthenticationError: (535, b'5.7.8 Username and Password not accepted. Learn more at\n5.7.8  https://support.google.com/mail/?p=BadCredentials z30sm8736685pfq.154 - gsmtp')

2020-01-09 20:19:18,575 INFO controller Points Captured. [(909, 617), (242, 680)]
2020-01-09 20:19:36,927 INFO controller all certificates generated successfully
2020-01-09 20:19:45,272 INFO controller mailer failed due to the following reason
2020-01-09 20:19:45,272 INFO controller Traceback (most recent call last):
  File "/Users/ajayraj/Documents/GitHub/Certificate-Generator/controller.py", line 146, in email_certificates
    mailer = Mailer(target_dir, mailing_list)
  File "/Users/ajayraj/Documents/GitHub/Certificate-Generator/mailer.py", line 26, in __init__
    self.server.login(self.login_email, self.login_password)
  File "/Library/Frameworks/Python.framework/Versions/3.6/lib/python3.6/smtplib.py", line 730, in login
    raise last_exception
  File "/Library/Frameworks/Python.framework/Versions/3.6/lib/python3.6/smtplib.py", line 721, in login
    initial_response_ok=initial_response_ok)
  File "/Library/Frameworks/Python.framework/Versions/3.6/lib/python3.6/smtplib.py", line 642, in auth
    raise SMTPAuthenticationError(code, resp)
smtplib.SMTPAuthenticationError: (535, b'5.7.8 Username and Password not accepted. Learn more at\n5.7.8  https://support.google.com/mail/?p=BadCredentials o7sm8969227pfg.138 - gsmtp')

2020-01-09 20:23:43,261 INFO controller Points Captured. []
2020-01-09 20:24:28,456 INFO controller Points Captured. []
2020-01-09 20:27:49,089 INFO controller Points Captured. []
2020-01-09 20:27:55,965 INFO controller generate_certificates() called before set_points()
2020-01-09 20:27:59,238 INFO controller generate_certificates() called before set_points()
2020-01-09 20:28:42,794 INFO controller Points Captured. [(1079, 635), (193, 697)]
2020-01-09 20:28:49,764 INFO controller all certificates generated successfully
2020-01-09 20:28:57,771 INFO controller mailer failed due to the following reason
2020-01-09 20:28:57,771 INFO controller Traceback (most recent call last):
  File "/Users/ajayraj/Documents/GitHub/Certificate-Generator/controller.py", line 146, in email_certificates
    mailer = Mailer(target_dir, mailing_list)
  File "/Users/ajayraj/Documents/GitHub/Certificate-Generator/mailer.py", line 26, in __init__
    self.server.login(self.login_email, self.login_password)
  File "/Library/Frameworks/Python.framework/Versions/3.6/lib/python3.6/smtplib.py", line 730, in login
    raise last_exception
  File "/Library/Frameworks/Python.framework/Versions/3.6/lib/python3.6/smtplib.py", line 721, in login
    initial_response_ok=initial_response_ok)
  File "/Library/Frameworks/Python.framework/Versions/3.6/lib/python3.6/smtplib.py", line 642, in auth
    raise SMTPAuthenticationError(code, resp)
smtplib.SMTPAuthenticationError: (535, b'5.7.8 Username and Password not accepted. Learn more at\n5.7.8  https://support.google.com/mail/?p=BadCredentials q6sm8291660pfh.127 - gsmtp')

2020-01-09 20:30:59,719 INFO controller Points Captured. [(920, 632), (245, 695)]
2020-01-09 20:31:04,553 INFO controller email_certificates() called before generate_certificates()
2020-01-09 20:31:07,319 INFO controller all certificates generated successfully
2020-01-09 20:31:30,190 INFO controller Emails dispatched successfully
2020-01-10 08:30:21,201 INFO controller Points Captured. [(900, 639), (216, 703)]
2020-01-10 08:30:25,508 INFO controller all certificates generated successfully
2020-01-10 08:30:49,206 INFO controller mailer failed due to the following reason
2020-01-10 08:30:49,206 INFO controller Traceback (most recent call last):
  File "/Users/ajayraj/Documents/GitHub/Certificate-Generator/controller.py", line 146, in email_certificates
    mailer = Mailer(target_dir, mailing_list)
  File "/Users/ajayraj/Documents/GitHub/Certificate-Generator/mailer.py", line 26, in __init__
    self.server.starttls()
  File "/Library/Frameworks/Python.framework/Versions/3.6/lib/python3.6/smtplib.py", line 771, in starttls
    server_hostname=self._host)
  File "/Library/Frameworks/Python.framework/Versions/3.6/lib/python3.6/ssl.py", line 401, in wrap_socket
    _context=self, _session=session)
  File "/Library/Frameworks/Python.framework/Versions/3.6/lib/python3.6/ssl.py", line 808, in __init__
    self.do_handshake()
  File "/Library/Frameworks/Python.framework/Versions/3.6/lib/python3.6/ssl.py", line 1061, in do_handshake
    self._sslobj.do_handshake()
  File "/Library/Frameworks/Python.framework/Versions/3.6/lib/python3.6/ssl.py", line 683, in do_handshake
    self._sslobj.do_handshake()
ssl.SSLEOFError: EOF occurred in violation of protocol (_ssl.c:748)

2020-01-10 08:31:35,654 INFO controller mailer failed due to the following reason
2020-01-10 08:31:35,654 INFO controller Traceback (most recent call last):
  File "/Users/ajayraj/Documents/GitHub/Certificate-Generator/controller.py", line 146, in email_certificates
    mailer = Mailer(target_dir, mailing_list)
  File "/Users/ajayraj/Documents/GitHub/Certificate-Generator/mailer.py", line 29, in __init__
    self.server.starttls()
ValueError: Password might have been removed for security concerns. Please add password

2020-01-10 08:32:37,603 INFO controller Points Captured. [(886, 623), (138, 689)]
2020-01-10 08:32:42,405 INFO controller all certificates generated successfully
2020-01-10 08:34:10,817 INFO controller Emails dispatched successfully
2020-01-10 08:57:22,122 INFO controller Points Captured. [(1086, 638), (195, 693)]
2020-01-10 08:57:26,111 INFO controller all certificates generated successfully
2020-01-10 08:57:27,912 INFO controller mailer failed due to the following reason
2020-01-10 08:57:27,913 INFO controller Traceback (most recent call last):
  File "/Users/ajayraj/Documents/GitHub/Certificate-Generator/controller.py", line 150, in email_certificates
    mailer = Mailer(target_dir, email_config, mailing_list)
  File "/Users/ajayraj/Documents/GitHub/Certificate-Generator/mailer.py", line 23, in __init__
    self.login_email = self.email_config['credentials']['loginemail']
KeyError: 'loginemail'

2020-01-10 08:58:37,677 INFO controller Points Captured. [(932, 628), (221, 689)]
2020-01-10 08:58:41,274 INFO controller all certificates generated successfully
2020-01-10 09:00:55,957 INFO controller mailer failed due to the following reason
2020-01-10 09:00:55,958 INFO controller Traceback (most recent call last):
  File "/Users/ajayraj/Documents/GitHub/Certificate-Generator/controller.py", line 150, in email_certificates
    mailer = Mailer(target_dir, email_config, mailing_list)
  File "/Users/ajayraj/Documents/GitHub/Certificate-Generator/mailer.py", line 32, in __init__
    self.server.login(self.login_email, self.login_password)
  File "/Library/Frameworks/Python.framework/Versions/3.6/lib/python3.6/smtplib.py", line 730, in login
    raise last_exception
  File "/Library/Frameworks/Python.framework/Versions/3.6/lib/python3.6/smtplib.py", line 721, in login
    initial_response_ok=initial_response_ok)
  File "/Library/Frameworks/Python.framework/Versions/3.6/lib/python3.6/smtplib.py", line 642, in auth
    raise SMTPAuthenticationError(code, resp)
smtplib.SMTPAuthenticationError: (535, b'5.7.8 Username and Password not accepted. Learn more at\n5.7.8  https://support.google.com/mail/?p=BadCredentials t137sm391501pgb.40 - gsmtp')

2020-01-10 09:03:17,349 INFO controller Points Captured. [(906, 634), (230, 685)]
2020-01-10 09:03:21,061 INFO controller all certificates generated successfully
2020-01-10 09:05:43,466 INFO controller mailer failed due to the following reason
2020-01-10 09:05:43,466 INFO controller Traceback (most recent call last):
  File "/Library/Frameworks/Python.framework/Versions/3.6/lib/python3.6/smtplib.py", line 387, in getreply
    line = self.file.readline(_MAXLINE + 1)
  File "/Library/Frameworks/Python.framework/Versions/3.6/lib/python3.6/socket.py", line 586, in readinto
    return self._sock.recv_into(b)
TimeoutError: [Errno 60] Operation timed out

During handling of the above exception, another exception occurred:

Traceback (most recent call last):
  File "/Users/ajayraj/Documents/GitHub/Certificate-Generator/controller.py", line 150, in email_certificates
    mailer = Mailer(target_dir, email_config, mailing_list)
  File "/Users/ajayraj/Documents/GitHub/Certificate-Generator/mailer.py", line 30, in __init__
    self.server.starttls()
  File "/Library/Frameworks/Python.framework/Versions/3.6/lib/python3.6/smtplib.py", line 749, in starttls
    self.ehlo_or_helo_if_needed()
  File "/Library/Frameworks/Python.framework/Versions/3.6/lib/python3.6/smtplib.py", line 600, in ehlo_or_helo_if_needed
    if not (200 <= self.ehlo()[0] <= 299):
  File "/Library/Frameworks/Python.framework/Versions/3.6/lib/python3.6/smtplib.py", line 441, in ehlo
    (code, msg) = self.getreply()
  File "/Library/Frameworks/Python.framework/Versions/3.6/lib/python3.6/smtplib.py", line 391, in getreply
    + str(e))
smtplib.SMTPServerDisconnected: Connection unexpectedly closed: [Errno 60] Operation timed out

2020-01-10 09:08:25,565 INFO controller Points Captured. [(926, 643), (190, 705)]
2020-01-10 09:08:28,987 INFO controller all certificates generated successfully
2020-01-10 09:09:59,832 INFO controller mailer failed due to the following reason
2020-01-10 09:09:59,832 INFO controller Traceback (most recent call last):
  File "/Users/ajayraj/Documents/GitHub/Certificate-Generator/controller.py", line 150, in email_certificates
    mailer = Mailer(target_dir, email_config, mailing_list)
  File "/Users/ajayraj/Documents/GitHub/Certificate-Generator/mailer.py", line 32, in __init__
    self.server.login(self.login_email, self.login_password)
  File "/Library/Frameworks/Python.framework/Versions/3.6/lib/python3.6/smtplib.py", line 730, in login
    raise last_exception
  File "/Library/Frameworks/Python.framework/Versions/3.6/lib/python3.6/smtplib.py", line 721, in login
    initial_response_ok=initial_response_ok)
  File "/Library/Frameworks/Python.framework/Versions/3.6/lib/python3.6/smtplib.py", line 642, in auth
    raise SMTPAuthenticationError(code, resp)
smtplib.SMTPAuthenticationError: (535, b'5.7.8 Username and Password not accepted. Learn more at\n5.7.8  https://support.google.com/mail/?p=BadCredentials g22sm393553pgk.85 - gsmtp')

2020-01-10 09:13:32,400 INFO controller Emails dispatched successfully
2020-01-10 09:25:22,746 INFO controller Points Captured. [(511, 327), (513, 409)]
2020-01-10 09:25:26,615 INFO controller all certificates generated successfully
2020-01-10 09:27:10,940 INFO controller Emails dispatched successfully
2020-01-10 14:58:15,632 INFO controller Points Captured. [(510, 331), (513, 415)]
2020-01-10 14:58:19,027 INFO controller all certificates generated successfully
2020-01-10 14:58:35,569 INFO controller Emails dispatched successfully
